<?xml version="1.0" ?>
<!-- =================================================================================== -->
<!-- |    This document was autogenerated by xacro from ivr.xacro                      | -->
<!-- |    EDITING THIS FILE BY HAND IS NOT RECOMMENDED                                 | -->
<!-- =================================================================================== -->
<robot name="ivr">
  <material name="lightblue">
    <color rgba="0.01 1.0 0.97 1.0"/>
  </material>
  <material name="blue">
    <color rgba="0.0 0.0 1.0 1.0"/>
  </material>
  <material name="gray">
    <color rgba="1.0 1.0 1.0 1.0"/>
  </material>
  <material name="lightgray">
    <color rgba="1.0 1.0 1.0 0.5"/>
  </material>
  <material name="red_frame">
    <color rgba="1.0 0.0 0.0 1.0"/>
  </material>
  <material name="green_frame">
    <color rgba="0.0 1.0 0.0 1.0"/>
  </material>
  <material name="blue_frame">
    <color rgba="0.0 0.0 1.0 1.0"/>
  </material>
  <link name="world"/>
  <link name="base_link"/>
  <joint name="WORLD_TO_BASE" type="fixed">
    <parent link="world"/>
    <child link="base_link"/>
    <origin rpy="0 0 0" xyz="0 0 0"/>
  </joint>
  <link name="BODY_LINK1"/>
  <link name="BODY_LINK2"/>
  <link name="BODY_LINK3"/>
  <link name="BODY_LINK4"/>
  <link name="BODY_LINK5"/>
  <joint name="BODY_JOINT_X" type="prismatic">
    <parent link="base_link"/>
    <child link="BODY_LINK1"/>
    <axis xyz="1 0 0"/>
    <origin rpy="0 0 0" xyz="0 0 0"/>
    <limit effort="0" lower="-5.0" upper="5.0" velocity="0"/>
  </joint>
  <joint name="BODY_JOINT_Y" type="prismatic">
    <parent link="BODY_LINK1"/>
    <child link="BODY_LINK2"/>
    <axis xyz="0 1 0"/>
    <origin rpy="0 0 0" xyz="0 0 0"/>
    <limit effort="0" lower="-5.0" upper="5.0" velocity="0"/>
  </joint>
  <joint name="BODY_JOINT_Z" type="prismatic">
    <parent link="BODY_LINK2"/>
    <child link="BODY_LINK3"/>
    <axis xyz="0 0 1"/>
    <origin rpy="0 0 0" xyz="0 0 0"/>
    <limit effort="0" lower="-5.0" upper="5.0" velocity="0"/>
  </joint>
  <joint name="BODY_JOINT_YAW" type="revolute">
    <parent link="BODY_LINK3"/>
    <child link="BODY_LINK4"/>
    <axis xyz="0 0 1"/>
    <origin rpy="0 0 0" xyz="0 0 0"/>
    <limit effort="0" lower="-3.141592653589793" upper="3.141592653589793" velocity="0"/>
  </joint>
  <joint name="BODY_JOINT_PITCH" type="revolute">
    <parent link="BODY_LINK4"/>
    <child link="BODY_LINK5"/>
    <axis xyz="0 1 0"/>
    <origin rpy="0 0 0" xyz="0 0 0"/>
    <limit effort="0" lower="-3.141592653589793" upper="3.141592653589793" velocity="0"/>
  </joint>
  <joint name="BODY_JOINT_ROLL" type="revolute">
    <parent link="BODY_LINK5"/>
    <child link="BODY"/>
    <axis xyz="1 0 0"/>
    <origin rpy="0 0 0" xyz="0 0 0"/>
    <limit effort="0" lower="-3.141592653589793" upper="3.141592653589793" velocity="0"/>
  </joint>
  <link name="BODY">
    <collision>
      <origin rpy="0 0 0" xyz="0 0 0.012499999999999997"/>
      <geometry>
        <box size="0.128 0.145 0.145"/>
      </geometry>
    </collision>
    <collision name="upper_body">
      <origin rpy="0 0 0" xyz="0 0 0.13849999999999998"/>
      <geometry>
        <box size="0.3 0.39 0.107"/>
      </geometry>
    </collision>
    <collision name="lower_plate">
      <origin rpy="0 0 0" xyz="0 0 -0.0625"/>
      <geometry>
        <box size="0.25 0.25 0.005"/>
      </geometry>
    </collision>
    <collision name="short_misumi_frame">
      <origin rpy="0 0 0" xyz="0 0 0.20700000000000002"/>
      <geometry>
        <box size="0.305 0.386 0.03"/>
      </geometry>
    </collision>
    <collision name="long_misumi_frame_front">
      <origin rpy="0 0 0" xyz="0.16749999999999998 0 0.20700000000000002"/>
      <geometry>
        <box size="0.03 0.5 0.03"/>
      </geometry>
    </collision>
    <collision name="long_misumi_frame_rear">
      <origin rpy="0 0 0" xyz="-0.16749999999999998 0 0.20700000000000002"/>
      <geometry>
        <box size="0.03 0.5 0.03"/>
      </geometry>
    </collision>
    <collision name="lidar_box">
      <origin rpy="0 0 0" xyz="0 0 0.238"/>
      <geometry>
        <box size="0.105 0.105 0.032"/>
      </geometry>
    </collision>
    <collision name="lidar_cylinder">
      <origin rpy="0 0 0" xyz="0 0 0.29035"/>
      <geometry>
        <cylinder length="0.0727" radius="0.05165"/>
      </geometry>
    </collision>
    <visual>
      <origin rpy="0 0 0" xyz="0 0 0.012499999999999997"/>
      <geometry>
        <box size="0.128 0.145 0.145"/>
      </geometry>
      <material name="lightgray"/>
    </visual>
    <visual name="upper_body">
      <origin rpy="0 0 0" xyz="0 0 0.13849999999999998"/>
      <geometry>
        <box size="0.3 0.39 0.107"/>
      </geometry>
      <material name="lightgray"/>
    </visual>
    <visual name="lower_plate">
      <origin rpy="0 0 0" xyz="0 0 -0.0625"/>
      <geometry>
        <box size="0.25 0.25 0.005"/>
      </geometry>
      <material name="lightgray"/>
    </visual>
    <visual name="short_misumi_frame">
      <origin rpy="0 0 0" xyz="0 0 0.20700000000000002"/>
      <geometry>
        <box size="0.305 0.386 0.03"/>
      </geometry>
      <material name="lightgray"/>
    </visual>
    <visual name="long_misumi_frame_front">
      <origin rpy="0 0 0" xyz="0.16749999999999998 0 0.20700000000000002"/>
      <geometry>
        <box size="0.03 0.5 0.03"/>
      </geometry>
      <material name="lightgray"/>
    </visual>
    <visual name="long_misumi_frame_rear">
      <origin rpy="0 0 0" xyz="-0.16749999999999998 0 0.20700000000000002"/>
      <geometry>
        <box size="0.03 0.5 0.03"/>
      </geometry>
      <material name="lightgray"/>
    </visual>
    <visual name="lidar_box">
      <origin rpy="0 0 0" xyz="0 0 0.238"/>
      <geometry>
        <box size="0.105 0.105 0.032"/>
      </geometry>
      <material name="lightgray"/>
    </visual>
    <visual name="lidar_cylinder">
      <origin rpy="0 0 0" xyz="0 0 0.29035"/>
      <geometry>
        <cylinder length="0.0727" radius="0.05165"/>
      </geometry>
      <material name="lightgray"/>
    </visual>
  </link>
  <joint name="ARM1_JOINT1" type="revolute">
    <parent link="BODY"/>
    <child link="ARM1_LINK1"/>
    <axis xyz="0 0 1"/>
    <origin rpy="0 -1.5707963267948966 0" xyz="-0.25 0 0"/>
    <limit effort="78.4" lower="-6.283185307179586" upper="6.283185307179586" velocity="2.4543692606170255"/>
  </joint>
  <link name="ARM1_LINK1">
    <collision>
      <geometry>
        <cylinder length="0.148" radius="0.038"/>
      </geometry>
      <origin rpy="0 0 0" xyz="0 0 -0.11199999999999999"/>
    </collision>
    <visual>
      <geometry>
        <cylinder length="0.148" radius="0.038"/>
      </geometry>
      <origin rpy="0 0 0" xyz="0 0 -0.11199999999999999"/>
      <material name="lightblue"/>
    </visual>
  </link>
  <joint name="ARM1_JOINT2" type="revolute">
    <parent link="ARM1_LINK1"/>
    <child link="ARM1_LINK2"/>
    <axis xyz="0 0 1"/>
    <origin rpy="1.5707963267948966 0 0" xyz="0 0 0"/>
    <limit effort="78.4" lower="-2.076942" upper="2.076942" velocity="2.4543692606170255"/>
  </joint>
  <link name="ARM1_LINK2">
    <collision>
      <geometry>
        <cylinder length="0.166" radius="0.038"/>
      </geometry>
      <origin rpy="0 0 0" xyz="0 0 0"/>
    </collision>
    <visual>
      <geometry>
        <cylinder length="0.166" radius="0.038"/>
      </geometry>
      <origin rpy="0 0 0" xyz="0 0 0"/>
      <material name="gray"/>
    </visual>
  </link>
  <joint name="ARM1_JOINT3" type="revolute">
    <parent link="ARM1_LINK2"/>
    <child link="ARM1_LINK3"/>
    <axis xyz="0 0 1"/>
    <origin rpy="-1.5707963267948966 0 0" xyz="0 0.23000000000000004 0"/>
    <limit effort="78.4" lower="-6.283185307179586" upper="6.283185307179586" velocity="2.4543692606170255"/>
  </joint>
  <link name="ARM1_LINK3">
    <collision>
      <geometry>
        <cylinder length="0.15400000000000003" radius="0.038"/>
      </geometry>
      <origin rpy="0 0 0" xyz="0 0 -0.11500000000000002"/>
    </collision>
    <visual>
      <geometry>
        <cylinder length="0.15400000000000003" radius="0.038"/>
      </geometry>
      <origin rpy="0 0 0" xyz="0 0 -0.11500000000000002"/>
      <material name="lightblue"/>
    </visual>
  </link>
  <joint name="ARM1_JOINT4" type="revolute">
    <parent link="ARM1_LINK3"/>
    <child link="ARM1_LINK4"/>
    <axis xyz="0 0 1"/>
    <origin rpy="1.5707963267948966 0 0" xyz="0 0 0"/>
    <limit effort="78.4" lower="-2.076942" upper="2.076942" velocity="2.4543692606170255"/>
  </joint>
  <link name="ARM1_LINK4">
    <collision>
      <geometry>
        <cylinder length="0.166" radius="0.038"/>
      </geometry>
      <origin rpy="0 0 0" xyz="0 0 0"/>
    </collision>
    <visual>
      <geometry>
        <cylinder length="0.166" radius="0.038"/>
      </geometry>
      <origin rpy="0 0 0" xyz="0 0 0"/>
      <material name="gray"/>
    </visual>
  </link>
  <joint name="ARM1_JOINT5" type="revolute">
    <parent link="ARM1_LINK4"/>
    <child link="ARM1_LINK5"/>
    <axis xyz="0 0 1"/>
    <origin rpy="-1.5707963267948966 0 0" xyz="0 0.23000000000000004 0"/>
    <limit effort="58.8" lower="-6.283185307179586" upper="6.283185307179586" velocity="3.2724923474893677"/>
  </joint>
  <link name="ARM1_LINK5">
    <collision>
      <geometry>
        <cylinder length="0.15400000000000003" radius="0.038"/>
      </geometry>
      <origin rpy="0 0 0" xyz="0 0 -0.11500000000000002"/>
    </collision>
    <visual>
      <geometry>
        <cylinder length="0.15400000000000003" radius="0.038"/>
      </geometry>
      <origin rpy="0 0 0" xyz="0 0 -0.11500000000000002"/>
      <material name="lightblue"/>
    </visual>
  </link>
  <joint name="ARM1_JOINT6" type="revolute">
    <parent link="ARM1_LINK5"/>
    <child link="ARM1_LINK6"/>
    <axis xyz="0 0 1"/>
    <origin rpy="1.5707963267948966 0 0" xyz="0 0 0"/>
    <limit effort="58.8" lower="-2.076942" upper="2.076942" velocity="3.2724923474893677"/>
  </joint>
  <link name="ARM1_LINK6">
    <collision>
      <geometry>
        <cylinder length="0.166" radius="0.038"/>
      </geometry>
      <origin rpy="0 0 0" xyz="0 0 0"/>
    </collision>
    <visual>
      <geometry>
        <cylinder length="0.166" radius="0.038"/>
      </geometry>
      <origin rpy="0 0 0" xyz="0 0 0"/>
      <material name="gray"/>
    </visual>
  </link>
  <joint name="ARM1_JOINT7" type="revolute">
    <parent link="ARM1_LINK6"/>
    <child link="ARM1_LINK7"/>
    <axis xyz="0 0 1"/>
    <origin rpy="-1.5707963267948966 0 0" xyz="0 0.12315000000000001 0"/>
    <limit effort="58.8" lower="-6.283185307179586" upper="6.283185307179586" velocity="3.2724923474893677"/>
  </joint>
  <link name="ARM1_LINK7">
    <collision>
      <geometry>
        <cylinder length="0.08515" radius="0.038"/>
      </geometry>
      <origin rpy="0 0 0" xyz="0 0 -0.042575"/>
    </collision>
    <visual>
      <geometry>
        <cylinder length="0.08515" radius="0.038"/>
      </geometry>
      <origin rpy="0 0 0" xyz="0 0 -0.042575"/>
      <material name="lightblue"/>
    </visual>
  </link>
  <joint name="ARM1_JOINT_TOOLCHANGER" type="fixed">
    <parent link="ARM1_LINK7"/>
    <child link="ARM1_TOOLCHANGER"/>
    <origin rpy="0 0 0" xyz="0 0 0.095"/>
  </joint>
  <link name="ARM1_TOOLCHANGER">
    <collision name="ft">
      <geometry>
        <cylinder length="0.045" radius="0.04"/>
      </geometry>
      <origin rpy="0 0 0" xyz="0 0 -0.07250000000000001"/>
    </collision>
    <collision name="tc">
      <geometry>
        <box size="0.0927 0.0594 0.05"/>
      </geometry>
      <origin rpy="0 0 0" xyz="0.016649999999999998 0 -0.025"/>
    </collision>
    <visual name="ft">
      <geometry>
        <cylinder length="0.045" radius="0.04"/>
      </geometry>
      <origin rpy="0 0 0" xyz="0 0 -0.07250000000000001"/>
      <material name="gray"/>
    </visual>
    <visual name="tc">
      <geometry>
        <box size="0.0927 0.0594 0.05"/>
      </geometry>
      <origin rpy="0 0 0" xyz="0.016649999999999998 0 -0.025"/>
      <material name="gray"/>
    </visual>
  </link>
  <joint name="ARM1_JOINT_CAM" type="fixed">
    <parent link="ARM1_TOOLCHANGER"/>
    <child link="ARM1_REALSENSE"/>
    <origin rpy="0 0 -0.7853981633974483" xyz="-0.074953 -0.028991 -0.07410000000000005"/>
  </joint>
  <link name="ARM1_REALSENSE">
    <visual name="camera">
      <geometry>
        <box size="0.09 0.025 0.0249"/>
      </geometry>
      <origin rpy="0 0 0" xyz="0.03250004187696723 0 -0.01245"/>
      <material name="gray"/>
    </visual>
    <collision name="camera">
      <geometry>
        <box size="0.09 0.025 0.0249"/>
      </geometry>
      <origin rpy="0 0 0" xyz="0.03250004187696723 0 -0.01245"/>
    </collision>
  </link>
  <joint name="ARM2_JOINT1" type="revolute">
    <parent link="BODY"/>
    <child link="ARM2_LINK1"/>
    <axis xyz="0 0 1"/>
    <origin rpy="0 -1.5707963267948966 3.141592653589793" xyz="0.25 0 0"/>
    <limit effort="78.4" lower="-6.283185307179586" upper="6.283185307179586" velocity="2.4543692606170255"/>
  </joint>
  <link name="ARM2_LINK1">
    <collision>
      <geometry>
        <cylinder length="0.148" radius="0.038"/>
      </geometry>
      <origin rpy="0 0 0" xyz="0 0 -0.11199999999999999"/>
    </collision>
    <visual>
      <geometry>
        <cylinder length="0.148" radius="0.038"/>
      </geometry>
      <origin rpy="0 0 0" xyz="0 0 -0.11199999999999999"/>
      <material name="lightblue"/>
    </visual>
  </link>
  <joint name="ARM2_JOINT2" type="revolute">
    <parent link="ARM2_LINK1"/>
    <child link="ARM2_LINK2"/>
    <axis xyz="0 0 1"/>
    <origin rpy="1.5707963267948966 0 0" xyz="0 0 0"/>
    <limit effort="78.4" lower="-2.076942" upper="2.076942" velocity="2.4543692606170255"/>
  </joint>
  <link name="ARM2_LINK2">
    <collision>
      <geometry>
        <cylinder length="0.166" radius="0.038"/>
      </geometry>
      <origin rpy="0 0 0" xyz="0 0 0"/>
    </collision>
    <visual>
      <geometry>
        <cylinder length="0.166" radius="0.038"/>
      </geometry>
      <origin rpy="0 0 0" xyz="0 0 0"/>
      <material name="gray"/>
    </visual>
  </link>
  <joint name="ARM2_JOINT3" type="revolute">
    <parent link="ARM2_LINK2"/>
    <child link="ARM2_LINK3"/>
    <axis xyz="0 0 1"/>
    <origin rpy="-1.5707963267948966 0 0" xyz="0 0.23000000000000004 0"/>
    <limit effort="78.4" lower="-6.283185307179586" upper="6.283185307179586" velocity="2.4543692606170255"/>
  </joint>
  <link name="ARM2_LINK3">
    <collision>
      <geometry>
        <cylinder length="0.15400000000000003" radius="0.038"/>
      </geometry>
      <origin rpy="0 0 0" xyz="0 0 -0.11500000000000002"/>
    </collision>
    <visual>
      <geometry>
        <cylinder length="0.15400000000000003" radius="0.038"/>
      </geometry>
      <origin rpy="0 0 0" xyz="0 0 -0.11500000000000002"/>
      <material name="lightblue"/>
    </visual>
  </link>
  <joint name="ARM2_JOINT4" type="revolute">
    <parent link="ARM2_LINK3"/>
    <child link="ARM2_LINK4"/>
    <axis xyz="0 0 1"/>
    <origin rpy="1.5707963267948966 0 0" xyz="0 0 0"/>
    <limit effort="78.4" lower="-2.076942" upper="2.076942" velocity="2.4543692606170255"/>
  </joint>
  <link name="ARM2_LINK4">
    <collision>
      <geometry>
        <cylinder length="0.166" radius="0.038"/>
      </geometry>
      <origin rpy="0 0 0" xyz="0 0 0"/>
    </collision>
    <visual>
      <geometry>
        <cylinder length="0.166" radius="0.038"/>
      </geometry>
      <origin rpy="0 0 0" xyz="0 0 0"/>
      <material name="gray"/>
    </visual>
  </link>
  <joint name="ARM2_JOINT5" type="revolute">
    <parent link="ARM2_LINK4"/>
    <child link="ARM2_LINK5"/>
    <axis xyz="0 0 1"/>
    <origin rpy="-1.5707963267948966 0 0" xyz="0 0.23000000000000004 0"/>
    <limit effort="58.8" lower="-6.283185307179586" upper="6.283185307179586" velocity="3.2724923474893677"/>
  </joint>
  <link name="ARM2_LINK5">
    <collision>
      <geometry>
        <cylinder length="0.15400000000000003" radius="0.038"/>
      </geometry>
      <origin rpy="0 0 0" xyz="0 0 -0.11500000000000002"/>
    </collision>
    <visual>
      <geometry>
        <cylinder length="0.15400000000000003" radius="0.038"/>
      </geometry>
      <origin rpy="0 0 0" xyz="0 0 -0.11500000000000002"/>
      <material name="lightblue"/>
    </visual>
  </link>
  <joint name="ARM2_JOINT6" type="revolute">
    <parent link="ARM2_LINK5"/>
    <child link="ARM2_LINK6"/>
    <axis xyz="0 0 1"/>
    <origin rpy="1.5707963267948966 0 0" xyz="0 0 0"/>
    <limit effort="58.8" lower="-2.076942" upper="2.076942" velocity="3.2724923474893677"/>
  </joint>
  <link name="ARM2_LINK6">
    <collision>
      <geometry>
        <cylinder length="0.166" radius="0.038"/>
      </geometry>
      <origin rpy="0 0 0" xyz="0 0 0"/>
    </collision>
    <visual>
      <geometry>
        <cylinder length="0.166" radius="0.038"/>
      </geometry>
      <origin rpy="0 0 0" xyz="0 0 0"/>
      <material name="gray"/>
    </visual>
  </link>
  <joint name="ARM2_JOINT7" type="revolute">
    <parent link="ARM2_LINK6"/>
    <child link="ARM2_LINK7"/>
    <axis xyz="0 0 1"/>
    <origin rpy="-1.5707963267948966 0 0" xyz="0 0.12315000000000001 0"/>
    <limit effort="58.8" lower="-6.283185307179586" upper="6.283185307179586" velocity="3.2724923474893677"/>
  </joint>
  <link name="ARM2_LINK7">
    <collision>
      <geometry>
        <cylinder length="0.08515" radius="0.038"/>
      </geometry>
      <origin rpy="0 0 0" xyz="0 0 -0.042575"/>
    </collision>
    <visual>
      <geometry>
        <cylinder length="0.08515" radius="0.038"/>
      </geometry>
      <origin rpy="0 0 0" xyz="0 0 -0.042575"/>
      <material name="lightblue"/>
    </visual>
  </link>
  <joint name="ARM2_JOINT_TOOLCHANGER" type="fixed">
    <parent link="ARM2_LINK7"/>
    <child link="ARM2_TOOLCHANGER"/>
    <origin rpy="0 0 0" xyz="0 0 0.095"/>
  </joint>
  <link name="ARM2_TOOLCHANGER">
    <collision name="ft">
      <geometry>
        <cylinder length="0.045" radius="0.04"/>
      </geometry>
      <origin rpy="0 0 0" xyz="0 0 -0.07250000000000001"/>
    </collision>
    <collision name="tc">
      <geometry>
        <box size="0.0927 0.0594 0.05"/>
      </geometry>
      <origin rpy="0 0 0" xyz="0.016649999999999998 0 -0.025"/>
    </collision>
    <visual name="ft">
      <geometry>
        <cylinder length="0.045" radius="0.04"/>
      </geometry>
      <origin rpy="0 0 0" xyz="0 0 -0.07250000000000001"/>
      <material name="gray"/>
    </visual>
    <visual name="tc">
      <geometry>
        <box size="0.0927 0.0594 0.05"/>
      </geometry>
      <origin rpy="0 0 0" xyz="0.016649999999999998 0 -0.025"/>
      <material name="gray"/>
    </visual>
  </link>
  <joint name="ARM2_JOINT_CAM" type="fixed">
    <parent link="ARM2_TOOLCHANGER"/>
    <child link="ARM2_REALSENSE"/>
    <origin rpy="0 0 -0.7853981633974483" xyz="-0.074953 -0.028991 -0.07410000000000005"/>
  </joint>
  <link name="ARM2_REALSENSE">
    <visual name="camera">
      <geometry>
        <box size="0.09 0.025 0.0249"/>
      </geometry>
      <origin rpy="0 0 0" xyz="0.03250004187696723 0 -0.01245"/>
      <material name="gray"/>
    </visual>
    <collision name="camera">
      <geometry>
        <box size="0.09 0.025 0.0249"/>
      </geometry>
      <origin rpy="0 0 0" xyz="0.03250004187696723 0 -0.01245"/>
    </collision>
  </link>
  <joint name="ARM3_JOINT1" type="revolute">
    <parent link="BODY"/>
    <child link="ARM3_LINK1"/>
    <axis xyz="0 0 1"/>
    <origin rpy="0 -1.5707963267948966 1.5707963267948966" xyz="0 -0.25 0"/>
    <limit effort="238.4" lower="-6.283185307179586" upper="6.283185307179586" velocity="1.4398966328953218"/>
  </joint>
  <link name="ARM3_LINK1">
    <collision>
      <geometry>
        <cylinder length="0.129" radius="0.0485"/>
      </geometry>
      <origin rpy="0 0 0" xyz="0 0 -0.113"/>
    </collision>
    <visual>
      <geometry>
        <cylinder length="0.129" radius="0.0485"/>
      </geometry>
      <origin rpy="0 0 0" xyz="0 0 -0.113"/>
      <material name="blue"/>
    </visual>
  </link>
  <joint name="ARM3_JOINT2" type="revolute">
    <parent link="ARM3_LINK1"/>
    <child link="ARM3_LINK2"/>
    <axis xyz="0 0 1"/>
    <origin rpy="1.5707963267948966 0 0" xyz="0 0 0"/>
    <limit effort="238.4" lower="-2.076942" upper="2.076942" velocity="1.4398966328953218"/>
  </joint>
  <link name="ARM3_LINK2">
    <collision>
      <geometry>
        <cylinder length="0.18" radius="0.0485"/>
      </geometry>
      <origin rpy="0 0 0" xyz="0 0 0"/>
    </collision>
    <visual>
      <geometry>
        <cylinder length="0.18" radius="0.0485"/>
      </geometry>
      <origin rpy="0 0 0" xyz="0 0 0"/>
      <material name="gray"/>
    </visual>
  </link>
  <joint name="ARM3_JOINT3" type="revolute">
    <parent link="ARM3_LINK2"/>
    <child link="ARM3_LINK3"/>
    <axis xyz="0 0 1"/>
    <origin rpy="-1.5707963267948966 0 0" xyz="0 0.23 0"/>
    <limit effort="238.4" lower="-6.283185307179586" upper="6.283185307179586" velocity="1.4398966328953218"/>
  </joint>
  <link name="ARM3_LINK3">
    <collision>
      <geometry>
        <cylinder length="0.133" radius="0.0485"/>
      </geometry>
      <origin rpy="0 0 0" xyz="0 0 -0.115"/>
    </collision>
    <visual>
      <geometry>
        <cylinder length="0.133" radius="0.0485"/>
      </geometry>
      <origin rpy="0 0 0" xyz="0 0 -0.115"/>
      <material name="blue"/>
    </visual>
  </link>
  <joint name="ARM3_JOINT4" type="revolute">
    <parent link="ARM3_LINK3"/>
    <child link="ARM3_LINK4"/>
    <axis xyz="0 0 1"/>
    <origin rpy="1.5707963267948966 0 0" xyz="0 0 0"/>
    <limit effort="238.4" lower="-2.076942" upper="2.076942" velocity="1.4398966328953218"/>
  </joint>
  <link name="ARM3_LINK4">
    <collision>
      <geometry>
        <cylinder length="0.18" radius="0.0485"/>
      </geometry>
      <origin rpy="0 0 0" xyz="0 0 0"/>
    </collision>
    <visual>
      <geometry>
        <cylinder length="0.18" radius="0.0485"/>
      </geometry>
      <origin rpy="0 0 0" xyz="0 0 0"/>
      <material name="gray"/>
    </visual>
  </link>
  <joint name="ARM3_JOINT5" type="revolute">
    <parent link="ARM3_LINK4"/>
    <child link="ARM3_LINK5"/>
    <axis xyz="0 0 1"/>
    <origin rpy="-1.5707963267948966 0 0" xyz="0 0.23 0"/>
    <limit effort="238.4" lower="-6.283185307179586" upper="6.283185307179586" velocity="1.4398966328953218"/>
  </joint>
  <link name="ARM3_LINK5">
    <collision>
      <geometry>
        <cylinder length="0.133" radius="0.0485"/>
      </geometry>
      <origin rpy="0 0 0" xyz="0 0 -0.115"/>
    </collision>
    <visual>
      <geometry>
        <cylinder length="0.133" radius="0.0485"/>
      </geometry>
      <origin rpy="0 0 0" xyz="0 0 -0.115"/>
      <material name="blue"/>
    </visual>
  </link>
  <joint name="ARM3_JOINT6" type="revolute">
    <parent link="ARM3_LINK5"/>
    <child link="ARM3_LINK6"/>
    <axis xyz="0 0 1"/>
    <origin rpy="1.5707963267948966 0 0" xyz="0 0 0"/>
    <limit effort="238.4" lower="-2.076942" upper="2.076942" velocity="1.4398966328953218"/>
  </joint>
  <link name="ARM3_LINK6">
    <collision>
      <geometry>
        <cylinder length="0.18" radius="0.0485"/>
      </geometry>
      <origin rpy="0 0 0" xyz="0 0 0"/>
    </collision>
    <visual>
      <geometry>
        <cylinder length="0.18" radius="0.0485"/>
      </geometry>
      <origin rpy="0 0 0" xyz="0 0 0"/>
      <material name="gray"/>
    </visual>
  </link>
  <joint name="ARM3_JOINT7" type="revolute">
    <parent link="ARM3_LINK6"/>
    <child link="ARM3_LINK7"/>
    <axis xyz="0 0 1"/>
    <origin rpy="-1.5707963267948966 0 0" xyz="0 0.159 0"/>
    <limit effort="238.4" lower="-6.283185307179586" upper="6.283185307179586" velocity="1.4398966328953218"/>
  </joint>
  <link name="ARM3_LINK7">
    <collision>
      <geometry>
        <cylinder length="0.1105" radius="0.0485"/>
      </geometry>
      <origin rpy="0 0 0" xyz="0 0 -0.05525"/>
    </collision>
    <visual>
      <geometry>
        <cylinder length="0.1105" radius="0.0485"/>
      </geometry>
      <origin rpy="0 0 0" xyz="0 0 -0.05525"/>
      <material name="blue"/>
    </visual>
  </link>
  <joint name="ARM3_JOINT_TOOLCHANGER" type="fixed">
    <parent link="ARM3_LINK7"/>
    <child link="ARM3_TOOLCHANGER"/>
    <origin rpy="0 0 0" xyz="0 0 0.12045"/>
  </joint>
  <link name="ARM3_TOOLCHANGER">
    <collision name="ft">
      <geometry>
        <cylinder length="0.057" radius="0.05"/>
      </geometry>
      <origin rpy="0 0 0" xyz="0 0 -0.09195"/>
    </collision>
    <collision name="tc">
      <geometry>
        <box size="0.1205 0.085 0.06345"/>
      </geometry>
      <origin rpy="0 0 0" xyz="0.017750000000000002 0 -0.031725"/>
    </collision>
    <visual name="ft">
      <geometry>
        <cylinder length="0.057" radius="0.05"/>
      </geometry>
      <origin rpy="0 0 0" xyz="0 0 -0.09195"/>
      <material name="gray"/>
    </visual>
    <visual name="tc">
      <geometry>
        <box size="0.1205 0.085 0.06345"/>
      </geometry>
      <origin rpy="0 0 0" xyz="0.017750000000000002 0 -0.031725"/>
      <material name="gray"/>
    </visual>
  </link>
  <joint name="ARM3_JOINT_CAM" type="fixed">
    <parent link="ARM3_TOOLCHANGER"/>
    <child link="ARM3_REALSENSE"/>
    <origin rpy="0 0 0" xyz="-0.0325 -0.0835 -0.09855000000000003"/>
  </joint>
  <link name="ARM3_REALSENSE">
    <visual name="camera">
      <geometry>
        <box size="0.09 0.025 0.0249"/>
      </geometry>
      <origin rpy="0 0 0" xyz="0.0325 0 -0.01245"/>
      <material name="gray"/>
    </visual>
    <collision name="camera">
      <geometry>
        <box size="0.09 0.025 0.0249"/>
      </geometry>
      <origin rpy="0 0 0" xyz="0.0325 0 -0.01245"/>
    </collision>
  </link>
  <joint name="ARM4_JOINT1" type="revolute">
    <parent link="BODY"/>
    <child link="ARM4_LINK1"/>
    <axis xyz="0 0 1"/>
    <origin rpy="0 -1.5707963267948966 -1.5707963267948966" xyz="0 0.25 0"/>
    <limit effort="238.4" lower="-6.283185307179586" upper="6.283185307179586" velocity="1.4398966328953218"/>
  </joint>
  <link name="ARM4_LINK1">
    <collision>
      <geometry>
        <cylinder length="0.129" radius="0.0485"/>
      </geometry>
      <origin rpy="0 0 0" xyz="0 0 -0.113"/>
    </collision>
    <visual>
      <geometry>
        <cylinder length="0.129" radius="0.0485"/>
      </geometry>
      <origin rpy="0 0 0" xyz="0 0 -0.113"/>
      <material name="blue"/>
    </visual>
  </link>
  <joint name="ARM4_JOINT2" type="revolute">
    <parent link="ARM4_LINK1"/>
    <child link="ARM4_LINK2"/>
    <axis xyz="0 0 1"/>
    <origin rpy="1.5707963267948966 0 0" xyz="0 0 0"/>
    <limit effort="238.4" lower="-2.076942" upper="2.076942" velocity="1.4398966328953218"/>
  </joint>
  <link name="ARM4_LINK2">
    <collision>
      <geometry>
        <cylinder length="0.18" radius="0.0485"/>
      </geometry>
      <origin rpy="0 0 0" xyz="0 0 0"/>
    </collision>
    <visual>
      <geometry>
        <cylinder length="0.18" radius="0.0485"/>
      </geometry>
      <origin rpy="0 0 0" xyz="0 0 0"/>
      <material name="gray"/>
    </visual>
  </link>
  <joint name="ARM4_JOINT3" type="revolute">
    <parent link="ARM4_LINK2"/>
    <child link="ARM4_LINK3"/>
    <axis xyz="0 0 1"/>
    <origin rpy="-1.5707963267948966 0 0" xyz="0 0.23 0"/>
    <limit effort="238.4" lower="-6.283185307179586" upper="6.283185307179586" velocity="1.4398966328953218"/>
  </joint>
  <link name="ARM4_LINK3">
    <collision>
      <geometry>
        <cylinder length="0.133" radius="0.0485"/>
      </geometry>
      <origin rpy="0 0 0" xyz="0 0 -0.115"/>
    </collision>
    <visual>
      <geometry>
        <cylinder length="0.133" radius="0.0485"/>
      </geometry>
      <origin rpy="0 0 0" xyz="0 0 -0.115"/>
      <material name="blue"/>
    </visual>
  </link>
  <joint name="ARM4_JOINT4" type="revolute">
    <parent link="ARM4_LINK3"/>
    <child link="ARM4_LINK4"/>
    <axis xyz="0 0 1"/>
    <origin rpy="1.5707963267948966 0 0" xyz="0 0 0"/>
    <limit effort="238.4" lower="-2.076942" upper="2.076942" velocity="1.4398966328953218"/>
  </joint>
  <link name="ARM4_LINK4">
    <collision>
      <geometry>
        <cylinder length="0.18" radius="0.0485"/>
      </geometry>
      <origin rpy="0 0 0" xyz="0 0 0"/>
    </collision>
    <visual>
      <geometry>
        <cylinder length="0.18" radius="0.0485"/>
      </geometry>
      <origin rpy="0 0 0" xyz="0 0 0"/>
      <material name="gray"/>
    </visual>
  </link>
  <joint name="ARM4_JOINT5" type="revolute">
    <parent link="ARM4_LINK4"/>
    <child link="ARM4_LINK5"/>
    <axis xyz="0 0 1"/>
    <origin rpy="-1.5707963267948966 0 0" xyz="0 0.23 0"/>
    <limit effort="238.4" lower="-6.283185307179586" upper="6.283185307179586" velocity="1.4398966328953218"/>
  </joint>
  <link name="ARM4_LINK5">
    <collision>
      <geometry>
        <cylinder length="0.133" radius="0.0485"/>
      </geometry>
      <origin rpy="0 0 0" xyz="0 0 -0.115"/>
    </collision>
    <visual>
      <geometry>
        <cylinder length="0.133" radius="0.0485"/>
      </geometry>
      <origin rpy="0 0 0" xyz="0 0 -0.115"/>
      <material name="blue"/>
    </visual>
  </link>
  <joint name="ARM4_JOINT6" type="revolute">
    <parent link="ARM4_LINK5"/>
    <child link="ARM4_LINK6"/>
    <axis xyz="0 0 1"/>
    <origin rpy="1.5707963267948966 0 0" xyz="0 0 0"/>
    <limit effort="238.4" lower="-2.076942" upper="2.076942" velocity="1.4398966328953218"/>
  </joint>
  <link name="ARM4_LINK6">
    <collision>
      <geometry>
        <cylinder length="0.18" radius="0.0485"/>
      </geometry>
      <origin rpy="0 0 0" xyz="0 0 0"/>
    </collision>
    <visual>
      <geometry>
        <cylinder length="0.18" radius="0.0485"/>
      </geometry>
      <origin rpy="0 0 0" xyz="0 0 0"/>
      <material name="gray"/>
    </visual>
  </link>
  <joint name="ARM4_JOINT7" type="revolute">
    <parent link="ARM4_LINK6"/>
    <child link="ARM4_LINK7"/>
    <axis xyz="0 0 1"/>
    <origin rpy="-1.5707963267948966 0 0" xyz="0 0.159 0"/>
    <limit effort="238.4" lower="-6.283185307179586" upper="6.283185307179586" velocity="1.4398966328953218"/>
  </joint>
  <link name="ARM4_LINK7">
    <collision>
      <geometry>
        <cylinder length="0.1105" radius="0.0485"/>
      </geometry>
      <origin rpy="0 0 0" xyz="0 0 -0.05525"/>
    </collision>
    <visual>
      <geometry>
        <cylinder length="0.1105" radius="0.0485"/>
      </geometry>
      <origin rpy="0 0 0" xyz="0 0 -0.05525"/>
      <material name="blue"/>
    </visual>
  </link>
  <joint name="ARM4_JOINT_TOOLCHANGER" type="fixed">
    <parent link="ARM4_LINK7"/>
    <child link="ARM4_TOOLCHANGER"/>
    <origin rpy="0 0 0" xyz="0 0 0.12045"/>
  </joint>
  <link name="ARM4_TOOLCHANGER">
    <collision name="ft">
      <geometry>
        <cylinder length="0.057" radius="0.05"/>
      </geometry>
      <origin rpy="0 0 0" xyz="0 0 -0.09195"/>
    </collision>
    <collision name="tc">
      <geometry>
        <box size="0.1205 0.085 0.06345"/>
      </geometry>
      <origin rpy="0 0 0" xyz="0.017750000000000002 0 -0.031725"/>
    </collision>
    <visual name="ft">
      <geometry>
        <cylinder length="0.057" radius="0.05"/>
      </geometry>
      <origin rpy="0 0 0" xyz="0 0 -0.09195"/>
      <material name="gray"/>
    </visual>
    <visual name="tc">
      <geometry>
        <box size="0.1205 0.085 0.06345"/>
      </geometry>
      <origin rpy="0 0 0" xyz="0.017750000000000002 0 -0.031725"/>
      <material name="gray"/>
    </visual>
  </link>
  <joint name="ARM4_JOINT_CAM" type="fixed">
    <parent link="ARM4_TOOLCHANGER"/>
    <child link="ARM4_REALSENSE"/>
    <origin rpy="0 0 0" xyz="-0.0325 -0.0835 -0.09855000000000003"/>
  </joint>
  <link name="ARM4_REALSENSE">
    <visual name="camera">
      <geometry>
        <box size="0.09 0.025 0.0249"/>
      </geometry>
      <origin rpy="0 0 0" xyz="0.0325 0 -0.01245"/>
      <material name="gray"/>
    </visual>
    <collision name="camera">
      <geometry>
        <box size="0.09 0.025 0.0249"/>
      </geometry>
      <origin rpy="0 0 0" xyz="0.0325 0 -0.01245"/>
    </collision>
  </link>
  <material name="yellow_ARM1">
    <color rgba="1.0 1.0 0.0 1.0"/>
  </material>
  <link name="ARM1_ENDEFFECTOR">
    <collision name="tool">
      <geometry>
        <box size="0.056 0.107 0.158587"/>
      </geometry>
      <origin rpy="0 0 0" xyz="0 0 -0.06009364000000002"/>
    </collision>
    <visual name="tool">
      <geometry>
        <box size="0.056 0.107 0.158587"/>
      </geometry>
      <origin rpy="0 0 0" xyz="0 0 -0.06009364000000002"/>
      <material name="yellow_ARM1"/>
    </visual>
  </link>
  <joint name="ARM1_JOINT_ENDEFFECTOR" type="fixed">
    <parent link="ARM1_TOOLCHANGER"/>
    <child link="ARM1_ENDEFFECTOR"/>
    <origin rpy="0 0 0" xyz="0 0 0.13938714000000002"/>
  </joint>
  <joint name="ARM1_JOINT_TOOL" type="fixed">
    <parent link="ARM1_ENDEFFECTOR"/>
    <child link="ARM1_TOOLFRAME"/>
    <origin rpy="3.141592653589793 -1.5707963267948966 0" xyz="0 0 0"/>
  </joint>
  <link name="ARM1_TOOLFRAME">
    <visual name="arrow_ee_x">
      <geometry>
        <cylinder length="0.1" radius="0.01"/>
      </geometry>
      <origin rpy="0 1.5707963267948966 0" xyz="0.05 0 0"/>
      <material name="red_frame"/>
    </visual>
    <visual name="arrow_ee_y">
      <geometry>
        <cylinder length="0.1" radius="0.01"/>
      </geometry>
      <origin rpy="1.5707963267948966 0 0" xyz="0 0.05 0"/>
      <material name="green_frame"/>
    </visual>
    <visual name="arrow_ee_z">
      <geometry>
        <cylinder length="0.1" radius="0.01"/>
      </geometry>
      <origin rpy="0 0 0" xyz="0 0 0.05"/>
      <material name="blue_frame"/>
    </visual>
  </link>
  <joint name="ARM1_GRASP" type="fixed">
    <parent link="ARM1_TOOLFRAME"/>
    <child link="grasp_link"/>
    <origin rpy="0 0 0" xyz="0 0 0"/>
  </joint>
  <link name="grasp_link">
  </link>
  <joint name="ARM1_GRIPPER" type="revolute">
    <parent link="grasp_link"/>
    <child link="gripper"/>
    <origin rpy="0 0 0" xyz="0 0 0"/>
    <axis xyz="0 0 1"/>
    <limit effort="78.4" lower="-6.283185307179586" upper="6.283185307179586" velocity="2.4543692606170255"/>
  </joint>
  <link name="gripper">
  </link>
  <material name="yellow_ARM2">
    <color rgba="1.0 1.0 0.0 1.0"/>
  </material>
  <link name="ARM2_ENDEFFECTOR">
    <collision name="tool">
      <geometry>
        <box size="0.056 0.107 0.158587"/>
      </geometry>
      <origin rpy="0 0 0" xyz="0 0 -0.06009364000000002"/>
    </collision>
    <visual name="tool">
      <geometry>
        <box size="0.056 0.107 0.158587"/>
      </geometry>
      <origin rpy="0 0 0" xyz="0 0 -0.06009364000000002"/>
      <material name="yellow_ARM2"/>
    </visual>
  </link>
  <joint name="ARM2_JOINT_ENDEFFECTOR" type="fixed">
    <parent link="ARM2_TOOLCHANGER"/>
    <child link="ARM2_ENDEFFECTOR"/>
    <origin rpy="0 0 0" xyz="0 0 0.13938714000000002"/>
  </joint>
  <joint name="ARM2_JOINT_TOOL" type="fixed">
    <parent link="ARM2_ENDEFFECTOR"/>
    <child link="ARM2_TOOLFRAME"/>
    <origin rpy="3.141592653589793 -1.5707963267948966 0" xyz="0 0 0"/>
  </joint>
  <link name="ARM2_TOOLFRAME">
    <visual name="arrow_ee_x">
      <geometry>
        <cylinder length="0.1" radius="0.01"/>
      </geometry>
      <origin rpy="0 1.5707963267948966 0" xyz="0.05 0 0"/>
      <material name="red_frame"/>
    </visual>
    <visual name="arrow_ee_y">
      <geometry>
        <cylinder length="0.1" radius="0.01"/>
      </geometry>
      <origin rpy="1.5707963267948966 0 0" xyz="0 0.05 0"/>
      <material name="green_frame"/>
    </visual>
    <visual name="arrow_ee_z">
      <geometry>
        <cylinder length="0.1" radius="0.01"/>
      </geometry>
      <origin rpy="0 0 0" xyz="0 0 0.05"/>
      <material name="blue_frame"/>
    </visual>
  </link>  
  <joint name="ARM2_GRASP" type="fixed">
    <parent link="ARM2_TOOLFRAME"/>
    <child link="grasp_link_2"/>
    <origin rpy="0 0 0" xyz="0 0 0"/>
  </joint>
  <link name="grasp_link_2">
  </link>
  <material name="yellow_ARM3">
    <color rgba="1.0 1.0 0.0 1.0"/>
  </material>
  <link name="ARM3_ENDEFFECTOR">
    <collision name="tool">
      <geometry>
        <box size="0.084 0.062 0.108"/>
      </geometry>
      <origin rpy="0 0 0" xyz="0 0 -0.054"/>
    </collision>
    <visual name="tool">
      <geometry>
        <box size="0.084 0.062 0.108"/>
      </geometry>
      <origin rpy="0 0 0" xyz="0 0 -0.054"/>
      <material name="yellow_ARM3"/>
    </visual>
  </link>
  <joint name="ARM3_JOINT_ENDEFFECTOR" type="fixed">
    <parent link="ARM3_TOOLCHANGER"/>
    <child link="ARM3_ENDEFFECTOR"/>
    <origin rpy="0 0 0" xyz="0 0 0.108"/>
  </joint>
  <joint name="ARM3_JOINT_TOOL" type="fixed">
    <parent link="ARM3_ENDEFFECTOR"/>
    <child link="ARM3_TOOLFRAME"/>
    <origin rpy="3.141592653589793 -1.5707963267948966 0" xyz="0 0 0"/>
  </joint>
  <link name="ARM3_TOOLFRAME">
    <visual name="arrow_ee_x">
      <geometry>
        <cylinder length="0.1" radius="0.01"/>
      </geometry>
      <origin rpy="0 1.5707963267948966 0" xyz="0.05 0 0"/>
      <material name="red_frame"/>
    </visual>
    <visual name="arrow_ee_y">
      <geometry>
        <cylinder length="0.1" radius="0.01"/>
      </geometry>
      <origin rpy="1.5707963267948966 0 0" xyz="0 0.05 0"/>
      <material name="green_frame"/>
    </visual>
    <visual name="arrow_ee_z">
      <geometry>
        <cylinder length="0.1" radius="0.01"/>
      </geometry>
      <origin rpy="0 0 0" xyz="0 0 0.05"/>
      <material name="blue_frame"/>
    </visual>
  </link>
  <joint name="ARM3_GRASP" type="fixed">
    <parent link="ARM3_TOOLFRAME"/>
    <child link="grasp_link_3"/>
    <origin rpy="0 0 0" xyz="0 0 0"/>
  </joint>
  <link name="grasp_link_3">
  </link>
  <material name="yellow_ARM4">
    <color rgba="1.0 1.0 0.0 1.0"/>
  </material>
  <link name="ARM4_ENDEFFECTOR">
    <collision name="tool">
      <geometry>
        <box size="0.084 0.062 0.108"/>
      </geometry>
      <origin rpy="0 0 0" xyz="0 0 -0.054"/>
    </collision>
    <visual name="tool">
      <geometry>
        <box size="0.084 0.062 0.108"/>
      </geometry>
      <origin rpy="0 0 0" xyz="0 0 -0.054"/>
      <material name="yellow_ARM4"/>
    </visual>
  </link>
  <joint name="ARM4_JOINT_ENDEFFECTOR" type="fixed">
    <parent link="ARM4_TOOLCHANGER"/>
    <child link="ARM4_ENDEFFECTOR"/>
    <origin rpy="0 0 0" xyz="0 0 0.108"/>
  </joint>
  <joint name="ARM4_JOINT_TOOL" type="fixed">
    <parent link="ARM4_ENDEFFECTOR"/>
    <child link="ARM4_TOOLFRAME"/>
    <origin rpy="3.141592653589793 -1.5707963267948966 0" xyz="0 0 0"/>
  </joint>
  <link name="ARM4_TOOLFRAME">
    <visual name="arrow_ee_x">
      <geometry>
        <cylinder length="0.1" radius="0.01"/>
      </geometry>
      <origin rpy="0 1.5707963267948966 0" xyz="0.05 0 0"/>
      <material name="red_frame"/>
    </visual>
    <visual name="arrow_ee_y">
      <geometry>
        <cylinder length="0.1" radius="0.01"/>
      </geometry>
      <origin rpy="1.5707963267948966 0 0" xyz="0 0.05 0"/>
      <material name="green_frame"/>
    </visual>
    <visual name="arrow_ee_z">
      <geometry>
        <cylinder length="0.1" radius="0.01"/>
      </geometry>
      <origin rpy="0 0 0" xyz="0 0 0.05"/>
      <material name="blue_frame"/>
    </visual>
  </link>
  <joint name="ARM4_GRASP" type="fixed">
    <parent link="ARM4_TOOLFRAME"/>
    <child link="grasp_link_4"/>
    <origin rpy="0 0 0" xyz="0 0 0"/>
  </joint>
  <link name="grasp_link_4">
  </link>
</robot>
